Traceback (most recent call last):
  File "/home/panxopanza/programs/miniconda3/lib/python3.9/site-packages/jupyter_cache/executors/utils.py", line 51, in single_nb_execution
    executenb(
  File "/home/panxopanza/programs/miniconda3/lib/python3.9/site-packages/nbclient/client.py", line 1204, in execute
    return NotebookClient(nb=nb, resources=resources, km=km, **kwargs).execute()
  File "/home/panxopanza/programs/miniconda3/lib/python3.9/site-packages/nbclient/util.py", line 84, in wrapped
    return just_run(coro(*args, **kwargs))
  File "/home/panxopanza/programs/miniconda3/lib/python3.9/site-packages/nbclient/util.py", line 62, in just_run
    return loop.run_until_complete(coro)
  File "/home/panxopanza/programs/miniconda3/lib/python3.9/asyncio/base_events.py", line 647, in run_until_complete
    return future.result()
  File "/home/panxopanza/programs/miniconda3/lib/python3.9/site-packages/nbclient/client.py", line 663, in async_execute
    await self.async_execute_cell(
  File "/home/panxopanza/programs/miniconda3/lib/python3.9/site-packages/nbclient/client.py", line 965, in async_execute_cell
    await self._check_raise_for_error(cell, cell_index, exec_reply)
  File "/home/panxopanza/programs/miniconda3/lib/python3.9/site-packages/nbclient/client.py", line 862, in _check_raise_for_error
    raise CellExecutionError.from_cell_and_msg(cell, exec_reply_content)
nbclient.exceptions.CellExecutionError: An error occurred while executing the following cell:
------------------
P = np.array([[1, 7], [2, 3], [5, 0]])
Q = np.array([[2, 6, 3, 1], [1, 2, 3, 4]])
print(P)
print(Q)
print(np.dot(P, Q))
np.dot(Q, P)
------------------

[0;31m---------------------------------------------------------------------------[0m
[0;31mValueError[0m                                Traceback (most recent call last)
[0;32m/tmp/ipykernel_729/3577237600.py[0m in [0;36m<module>[0;34m[0m
[1;32m      4[0m [0mprint[0m[0;34m([0m[0mQ[0m[0;34m)[0m[0;34m[0m[0;34m[0m[0m
[1;32m      5[0m [0mprint[0m[0;34m([0m[0mnp[0m[0;34m.[0m[0mdot[0m[0;34m([0m[0mP[0m[0;34m,[0m [0mQ[0m[0;34m)[0m[0;34m)[0m[0;34m[0m[0;34m[0m[0m
[0;32m----> 6[0;31m [0mnp[0m[0;34m.[0m[0mdot[0m[0;34m([0m[0mQ[0m[0;34m,[0m [0mP[0m[0;34m)[0m[0;34m[0m[0;34m[0m[0m
[0m
[0;32m~/programs/miniconda3/lib/python3.9/site-packages/numpy/core/overrides.py[0m in [0;36mdot[0;34m(*args, **kwargs)[0m

[0;31mValueError[0m: shapes (2,4) and (3,2) not aligned: 4 (dim 1) != 3 (dim 0)
ValueError: shapes (2,4) and (3,2) not aligned: 4 (dim 1) != 3 (dim 0)

