Traceback (most recent call last):
  File "/home/panxopanza/s/miniconda3/lib/python3.9/site-packages/jupyter_cache/executors/utils.py", line 51, in single_nb_execution
    executenb(
  File "/home/panxopanza/s/miniconda3/lib/python3.9/site-packages/nbclient/client.py", line 1204, in execute
    return NotebookClient(nb=nb, resources=resources, km=km, **kwargs).execute()
  File "/home/panxopanza/s/miniconda3/lib/python3.9/site-packages/nbclient/util.py", line 84, in wrapped
    return just_run(coro(*args, **kwargs))
  File "/home/panxopanza/s/miniconda3/lib/python3.9/site-packages/nbclient/util.py", line 62, in just_run
    return loop.run_until_complete(coro)
  File "/home/panxopanza/s/miniconda3/lib/python3.9/asyncio/base_events.py", line 647, in run_until_complete
    return future.result()
  File "/home/panxopanza/s/miniconda3/lib/python3.9/site-packages/nbclient/client.py", line 663, in async_execute
    await self.async_execute_cell(
  File "/home/panxopanza/s/miniconda3/lib/python3.9/site-packages/nbclient/client.py", line 965, in async_execute_cell
    await self._check_raise_for_error(cell, cell_index, exec_reply)
  File "/home/panxopanza/s/miniconda3/lib/python3.9/site-packages/nbclient/client.py", line 862, in _check_raise_for_error
    raise CellExecutionError.from_cell_and_msg(cell, exec_reply_content)
nbclient.exceptions.CellExecutionError: An error occurred while executing the following cell:
------------------
P = np.array([[1, 7], [2, 3], [5, 0]])
Q = np.array([[2, 6, 3, 1], [1, 2, 3, 4]])
print(P)
print(Q)
print(np.dot(P, Q))
np.dot(Q, P)
------------------

[0;31m---------------------------------------------------------------------------[0m
[0;31mValueError[0m                                Traceback (most recent call last)
Input [0;32mIn [6][0m, in [0;36m<cell line: 6>[0;34m()[0m
[1;32m      4[0m [38;5;28mprint[39m(Q)
[1;32m      5[0m [38;5;28mprint[39m(np[38;5;241m.[39mdot(P, Q))
[0;32m----> 6[0m [43mnp[49m[38;5;241;43m.[39;49m[43mdot[49m[43m([49m[43mQ[49m[43m,[49m[43m [49m[43mP[49m[43m)[49m

File [0;32m<__array_function__ internals>:180[0m, in [0;36mdot[0;34m(*args, **kwargs)[0m

[0;31mValueError[0m: shapes (2,4) and (3,2) not aligned: 4 (dim 1) != 3 (dim 0)
ValueError: shapes (2,4) and (3,2) not aligned: 4 (dim 1) != 3 (dim 0)

